Workbook

Sheet Parámetros
A1: Parámetros del cálculo
A2: Todos los valores fijos están aquí. Las fórmulas de las otras hojas los usan por su nombre (ej. RMV, TASA_ONP). Celdas en azul = valores fijos.
A4: Parámetro | B4: Valor | C4: Nombre en fórmulas | D4: Fecha de consulta | E4: Fuente
A5: Remuneración Mínima Vital (RMV) | B5: 1230 | C5: RMV | D5: 28/10/2026 | E5: D.S. N.° 015-2026-TR (El Peruano, 28/09/2026), vigente desde el 01/10/2026
A6: Asignación familiar (% de la RMV) | B6: 0.1 | C6: PCT_ASIG | D6: 28/10/2026 | E6: Ley 25129
A7: Asignación familiar (monto) | B7: =ROUND(RMV*PCT_ASIG,2) -> 123 | C7: ASIG_FAMILIAR | D7: 28/10/2026 | E7: Calculado: RMV × 10%
A8: ONP | B8: 0.13 | C8: TASA_ONP | D8: 28/10/2026 | E8: D.L. 19990
A9: EsSalud (lo paga el empleador) | B9: 0.09 | C9: TASA_ESSALUD | D9: 28/10/2026 | E9: Ley 26790
A10: Recargo horas extras (primeras horas) | B10: 0.25 | C10: RECARGO_25 | D10: 28/10/2026 | E10: D.S. 007-2002-TR (jornada y sobretiempo)
A11: Recargo horas extras (siguientes) | B11: 0.35 | C11: RECARGO_35 | D11: 28/10/2026 | E11: D.S. 007-2002-TR (jornada y sobretiempo)
A12: Días del mes (convención) | B12: 30 | C12: DIAS_MES | D12: 28/10/2026 | E12: Convención de la actividad
A13: Horas por día (convención) | B13: 8 | C13: HORAS_DIA | D13: 28/10/2026 | E13: Convención de la actividad
A16: Tasas de las AFP
A17: AFP | B17: Fondo | C17: Comisión | D17: Seguro | E17: Fuente | F17: Fecha de consulta
A18: AFP Ejemplo | B18: 0.1 | C18: 0.016 | D18: 0.0135 | E18: Valores de prueba del enunciado (solo para los casos 3 y 4) | F18: 28/10/2026
A19: Habitat (flujo) | B19: 0.1 | C19: 0.0147 | D19: 0.0137 | E19: SBS, comisiones y primas, devengue octubre 2026 | F19: 28/10/2026
A20: Integra (flujo) | B20: 0.1 | C20: 0.0155 | D20: 0.0137 | E20: SBS, comisiones y primas, devengue octubre 2026 | F20: 28/10/2026
A21: Prima (flujo) | B21: 0.1 | C21: 0.016 | D21: 0.0137 | E21: SBS, comisiones y primas, devengue octubre 2026 | F21: 28/10/2026
A22: Profuturo (flujo) | B22: 0.1 | C22: 0.0169 | D22: 0.0137 | E22: SBS, comisiones y primas, devengue octubre 2026 | F22: 28/10/2026
A24: Nota: las AFP reales se cargan con comisión sobre flujo. La prima de seguro real tiene tope (remuneración máxima asegurable S/ 12,732.70 en oct-2026); el modelo del curso no lo aplica, y en nuestros casos no influye porque ningún sueldo llega a ese tope.

Sheet Boleta
A1: Boleta de ejemplo
A2: Del sueldo al neto · Escribe los datos en las celdas amarillas (los mismos campos de la app). Todo lo demás se calcula solo con fórmulas.
A4: Dato de entrada | B4: Valor | C4: Regla | D4: Nota que muestra la app
A5: Sueldo básico (S/) | B5: 2500 | C5: Mayor que cero
A6: Días laborados | B6: 30 | C6: Entero entre 1 y 30
A7: ¿Tiene hijos? | B7: No | C7: No / Sí
A8: Sistema de pensiones | B8: ONP | C8: ONP / AFP
A9: AFP (solo si eligió AFP) | B9: AFP Ejemplo | C9: Lista de la hoja Parámetros | D9: =IF(B8<>"AFP","",IF(B9="AFP Ejemplo","Tasas de prueba: fondo 10%, comisión 1.60%, seguro 1.35%.","Tasas SBS de octubre 2026. Comisión sobre flujo; modelo simplificado sin tope de seguro."))
A10: Horas extras 25% | B10: 0 | C10: Mayor o igual a cero
A11: Horas extras 35% | B11: 0 | C11: Mayor o igual a cero
A12: Adelantos (S/) | B12: 0 | C12: Mayor o igual a cero
A14: Validación | B14: =IF(OR(NOT(ISNUMBER(B6)),B6<1,B6>30,B6<>INT(B6)),"Los días laborados deben ser un entero entre 1 y 30.",IF(OR(NOT(ISNUMBER(B5)),B5<0),"Sueldo básico: ingresa un número no negativo, sin separadores de miles (hasta 12 enteros y 6 decimales).",IF(OR(NOT(ISNUMBER(B10)),B10<0),"Horas al 25%: ingresa un número no negativo, sin separadores de miles (hasta 12 enteros y 6 decimales).",IF(OR(NOT(ISNUMBER(B11)),B11<0),"Horas al 35%: ingresa un número no negativo, sin separadores de miles (hasta 12 enteros y 6 decimales).",IF(OR(NOT(ISNUMBER(B12)),B12<0),"Adelantos: ingresa un número no negativo, sin separadores de miles (hasta 12 enteros y 6 decimales).",IF(B5=0,"El sueldo básico debe ser mayor que cero.",IF(AND(B8="AFP",ISNA(MATCH(B9,LISTA_AFP,0))),"Selecciona una AFP válida.","OK"))))))) -> OK
A15: Valor hora (auxiliar, no se suma) | B15: =B5/DIAS_MES/HORAS_DIA -> 10.416667
A17: REMUNERACIONES | B17: S/ | C17: RETENCIONES / DESCUENTOS | D17: S/ | E17: APORTACIONES DEL EMPLEADOR | F17: S/
A18: Sueldo computable | B18: =ROUND(B5/DIAS_MES*B6,2) -> 2500 | C18: ONP | D18: =IF(B8="ONP",ROUND(B23*TASA_ONP,2),0) -> 325 | E18: EsSalud (9%) | F18: =ROUND(B23*TASA_ESSALUD,2) -> 225
A19: Asignación familiar | B19: =IF(B7="Sí",ASIG_FAMILIAR,0) -> 0 | C19: AFP fondo | D19: =IF(B8="AFP",ROUND(B23*IFERROR(VLOOKUP(B9,TABLA_AFP,2,FALSE()),0),2),0) -> 0 | E19: Lo paga el empleador. No se resta de tu neto.
A20: Horas extras 25% | B20: =ROUND(B15*(1+RECARGO_25)*B10,2) -> 0 | C20: AFP comisión | D20: =IF(B8="AFP",ROUND(B23*IFERROR(VLOOKUP(B9,TABLA_AFP,3,FALSE()),0),2),0) -> 0
A21: Horas extras 35% | B21: =ROUND(B15*(1+RECARGO_35)*B11,2) -> 0 | C21: AFP seguro | D21: =IF(B8="AFP",ROUND(B23*IFERROR(VLOOKUP(B9,TABLA_AFP,4,FALSE()),0),2),0) -> 0
C22: Adelantos | D22: =ROUND(B12,2) -> 0
A23: Total remuneraciones | B23: =SUM(B18:B21) -> 2500 | C23: Total descuentos | D23: =SUM(D18:D22) -> 325
A25: NETO A PAGAR (S/) | B25: =IF(B14="OK",B23-D23,"—") -> 2175 | C25: =IF(B14<>"OK","No se calcula: "&B14,IF(B25<0,"El adelanto supera el saldo disponible.",""))
A27: RMV S/ 1,230 · Consulta: 28/10/2026. Modelo académico sin renta de quinta categoría ni bases mínimas de EsSalud.
A29: Extra para el análisis (no aparece en la app)
A30: Costo total para la empresa (remuneraciones + EsSalud) | B30: =IF(B14="OK",B23+F18,"—") -> 2725
A31: % del sueldo bruto que llega al trabajador | B31: =IF(B14<>"OK","—",IF(B23=0,0,B25/B23)) -> 0.87

Sheet Casos
A1: Casos de prueba y control cruzado con la app
A2: Cada fila es una boleta completa. Amarillo = datos que se ingresan en la app; el resto son las mismas fórmulas de la hoja Boleta. Las columnas 'app' son lo que muestra la app para esos mismos datos (comprobado con las pruebas de BoletaTests.swift).
A4: Caso | B4: Descripción | C4: Sueldo | D4: Días | E4: Hijos | F4: Sistema | G4: AFP | H4: HE 25% | I4: HE 35% | J4: Adelanto | K4: Valor hora | L4: Sueldo computable | M4: Asig. familiar | N4: HE 25% S/ | O4: HE 35% S/ | P4: Total remuneraciones | Q4: ONP | R4: AFP fondo | S4: AFP comisión | T4: AFP seguro | U4: Adelantos | V4: Total descuentos | W4: Neto a pagar | X4: EsSalud | Y4: % neto / bruto | Z4: Neto esperado (enunciado) | AA4: Total rem. app | AB4: Total desc. app | AC4: Neto app | AD4: EsSalud app | AE4: Diferencia Excel − app | AF4: ¿Coincide?
A5: 1 | B5: Sin hijos, ONP, mes completo | C5: 2500 | D5: 30 | E5: No | F5: ONP | G5: AFP Ejemplo | H5: 0 | I5: 0 | J5: 0 | K5: =C5/DIAS_MES/HORAS_DIA -> 10.416667 | L5: =ROUND(C5/DIAS_MES*D5,2) -> 2500 | M5: =IF(E5="Sí",ASIG_FAMILIAR,0) -> 0 | N5: =ROUND(K5*(1+RECARGO_25)*H5,2) -> 0 | O5: =ROUND(K5*(1+RECARGO_35)*I5,2) -> 0 | P5: =SUM(L5:O5) -> 2500 | Q5: =IF(F5="ONP",ROUND(P5*TASA_ONP,2),0) -> 325 | R5: =IF(F5="AFP",ROUND(P5*IFERROR(VLOOKUP(G5,TABLA_AFP,2,FALSE()),0),2),0) -> 0 | S5: =IF(F5="AFP",ROUND(P5*IFERROR(VLOOKUP(G5,TABLA_AFP,3,FALSE()),0),2),0) -> 0 | T5: =IF(F5="AFP",ROUND(P5*IFERROR(VLOOKUP(G5,TABLA_AFP,4,FALSE()),0),2),0) -> 0 | U5: =ROUND(J5,2) -> 0 | V5: =SUM(Q5:U5) -> 325 | W5: =P5-V5 -> 2175 | X5: =ROUND(P5*TASA_ESSALUD,2) -> 225 | Y5: =IF(P5=0,0,W5/P5) -> 0.87 | Z5: 2175 | AA5: 2500 | AB5: 325 | AC5: 2175 | AD5: 225 | AE5: =ROUND(IF(AA5="",0,ABS(P5-AA5))+IF(AB5="",0,ABS(V5-AB5))+IF(AC5="",0,ABS(W5-AC5))+IF(AD5="",0,ABS(X5-AD5)),2) -> 0 | AF5: =IF(AE5<>0,"Revisar",IF(Z5="—","Sí",IF(ROUND(W5-Z5,2)=0,"Sí","Revisar"))) -> Sí
A6: 2 | B6: Con hijos, días incompletos | C6: 1800 | D6: 27 | E6: Sí | F6: ONP | G6: AFP Ejemplo | H6: 0 | I6: 0 | J6: 0 | K6: =C6/DIAS_MES/HORAS_DIA -> 7.5 | L6: =ROUND(C6/DIAS_MES*D6,2) -> 1620 | M6: =IF(E6="Sí",ASIG_FAMILIAR,0) -> 123 | N6: =ROUND(K6*(1+RECARGO_25)*H6,2) -> 0 | O6: =ROUND(K6*(1+RECARGO_35)*I6,2) -> 0 | P6: =SUM(L6:O6) -> 1743 | Q6: =IF(F6="ONP",ROUND(P6*TASA_ONP,2),0) -> 226.59 | R6: =IF(F6="AFP",ROUND(P6*IFERROR(VLOOKUP(G6,TABLA_AFP,2,FALSE()),0),2),0) -> 0 | S6: =IF(F6="AFP",ROUND(P6*IFERROR(VLOOKUP(G6,TABLA_AFP,3,FALSE()),0),2),0) -> 0 | T6: =IF(F6="AFP",ROUND(P6*IFERROR(VLOOKUP(G6,TABLA_AFP,4,FALSE()),0),2),0) -> 0 | U6: =ROUND(J6,2) -> 0 | V6: =SUM(Q6:U6) -> 226.59 | W6: =P6-V6 -> 1516.41 | X6: =ROUND(P6*TASA_ESSALUD,2) -> 156.87 | Y6: =IF(P6=0,0,W6/P6) -> 0.87 | Z6: 1516.41 | AA6: 1743 | AB6: 226.59 | AC6: 1516.41 | AD6: 156.87 | AE6: =ROUND(IF(AA6="",0,ABS(P6-AA6))+IF(AB6="",0,ABS(V6-AB6))+IF(AC6="",0,ABS(W6-AC6))+IF(AD6="",0,ABS(X6-AD6)),2) -> 0 | AF6: =IF(AE6<>0,"Revisar",IF(Z6="—","Sí",IF(ROUND(W6-Z6,2)=0,"Sí","Revisar"))) -> Sí
A7: 3 | B7: AFP, horas extras y adelanto | C7: 3000 | D7: 30 | E7: Sí | F7: AFP | G7: AFP Ejemplo | H7: 4 | I7: 4 | J7: 200 | K7: =C7/DIAS_MES/HORAS_DIA -> 12.5 | L7: =ROUND(C7/DIAS_MES*D7,2) -> 3000 | M7: =IF(E7="Sí",ASIG_FAMILIAR,0) -> 123 | N7: =ROUND(K7*(1+RECARGO_25)*H7,2) -> 62.5 | O7: =ROUND(K7*(1+RECARGO_35)*I7,2) -> 67.5 | P7: =SUM(L7:O7) -> 3253 | Q7: =IF(F7="ONP",ROUND(P7*TASA_ONP,2),0) -> 0 | R7: =IF(F7="AFP",ROUND(P7*IFERROR(VLOOKUP(G7,TABLA_AFP,2,FALSE()),0),2),0) -> 325.3 | S7: =IF(F7="AFP",ROUND(P7*IFERROR(VLOOKUP(G7,TABLA_AFP,3,FALSE()),0),2),0) -> 52.05 | T7: =IF(F7="AFP",ROUND(P7*IFERROR(VLOOKUP(G7,TABLA_AFP,4,FALSE()),0),2),0) -> 43.92 | U7: =ROUND(J7,2) -> 200 | V7: =SUM(Q7:U7) -> 621.27 | W7: =P7-V7 -> 2631.73 | X7: =ROUND(P7*TASA_ESSALUD,2) -> 292.77 | Y7: =IF(P7=0,0,W7/P7) -> 0.80901629 | Z7: 2631.73 | AA7: 3253 | AB7: 621.27 | AC7: 2631.73 | AD7: 292.77 | AE7: =ROUND(IF(AA7="",0,ABS(P7-AA7))+IF(AB7="",0,ABS(V7-AB7))+IF(AC7="",0,ABS(W7-AC7))+IF(AD7="",0,ABS(X7-AD7)),2) -> 0 | AF7: =IF(AE7<>0,"Revisar",IF(Z7="—","Sí",IF(ROUND(W7-Z7,2)=0,"Sí","Revisar"))) -> Sí
A8: 4 | B8: Evaluación (lo revisa el docente) | C8: 4200 | D8: 24 | E8: Sí | F8: AFP | G8: AFP Ejemplo | H8: 2 | I8: 2 | J8: 100 | K8: =C8/DIAS_MES/HORAS_DIA -> 17.5 | L8: =ROUND(C8/DIAS_MES*D8,2) -> 3360 | M8: =IF(E8="Sí",ASIG_FAMILIAR,0) -> 123 | N8: =ROUND(K8*(1+RECARGO_25)*H8,2) -> 43.75 | O8: =ROUND(K8*(1+RECARGO_35)*I8,2) -> 47.25 | P8: =SUM(L8:O8) -> 3574 | Q8: =IF(F8="ONP",ROUND(P8*TASA_ONP,2),0) -> 0 | R8: =IF(F8="AFP",ROUND(P8*IFERROR(VLOOKUP(G8,TABLA_AFP,2,FALSE()),0),2),0) -> 357.4 | S8: =IF(F8="AFP",ROUND(P8*IFERROR(VLOOKUP(G8,TABLA_AFP,3,FALSE()),0),2),0) -> 57.18 | T8: =IF(F8="AFP",ROUND(P8*IFERROR(VLOOKUP(G8,TABLA_AFP,4,FALSE()),0),2),0) -> 48.25 | U8: =ROUND(J8,2) -> 100 | V8: =SUM(Q8:U8) -> 562.83 | W8: =P8-V8 -> 3011.17 | X8: =ROUND(P8*TASA_ESSALUD,2) -> 321.66 | Y8: =IF(P8=0,0,W8/P8) -> 0.84252098 | Z8: — | AA8: 3574 | AB8: 562.83 | AC8: 3011.17 | AD8: 321.66 | AE8: =ROUND(IF(AA8="",0,ABS(P8-AA8))+IF(AB8="",0,ABS(V8-AB8))+IF(AC8="",0,ABS(W8-AC8))+IF(AD8="",0,ABS(X8-AD8)),2) -> 0 | AF8: =IF(AE8<>0,"Revisar",IF(Z8="—","Sí",IF(ROUND(W8-Z8,2)=0,"Sí","Revisar"))) -> Sí
A9: Propio 1 | B9: Mi caso propio · ASO Developer Junior (LYNXUS Solutions) | C9: 2300 | D9: 30 | E9: No | F9: ONP | G9: AFP Ejemplo | H9: 0 | I9: 0 | J9: 0 | K9: =C9/DIAS_MES/HORAS_DIA -> 9.5833333 | L9: =ROUND(C9/DIAS_MES*D9,2) -> 2300 | M9: =IF(E9="Sí",ASIG_FAMILIAR,0) -> 0 | N9: =ROUND(K9*(1+RECARGO_25)*H9,2) -> 0 | O9: =ROUND(K9*(1+RECARGO_35)*I9,2) -> 0 | P9: =SUM(L9:O9) -> 2300 | Q9: =IF(F9="ONP",ROUND(P9*TASA_ONP,2),0) -> 299 | R9: =IF(F9="AFP",ROUND(P9*IFERROR(VLOOKUP(G9,TABLA_AFP,2,FALSE()),0),2),0) -> 0 | S9: =IF(F9="AFP",ROUND(P9*IFERROR(VLOOKUP(G9,TABLA_AFP,3,FALSE()),0),2),0) -> 0 | T9: =IF(F9="AFP",ROUND(P9*IFERROR(VLOOKUP(G9,TABLA_AFP,4,FALSE()),0),2),0) -> 0 | U9: =ROUND(J9,2) -> 0 | V9: =SUM(Q9:U9) -> 299 | W9: =P9-V9 -> 2001 | X9: =ROUND(P9*TASA_ESSALUD,2) -> 207 | Y9: =IF(P9=0,0,W9/P9) -> 0.87 | Z9: — | AA9: 2300 | AB9: 299 | AC9: 2001 | AD9: 207 | AE9: =ROUND(IF(AA9="",0,ABS(P9-AA9))+IF(AB9="",0,ABS(V9-AB9))+IF(AC9="",0,ABS(W9-AC9))+IF(AD9="",0,ABS(X9-AD9)),2) -> 0 | AF9: =IF(AE9<>0,"Revisar",IF(Z9="—","Sí",IF(ROUND(W9-Z9,2)=0,"Sí","Revisar"))) -> Sí
A10: Propio 2 | B10: Segundo sueldo real para comparar · Modelador BIM de Estructuras (Typsa Perú) | C10: 2500 | D10: 30 | E10: No | F10: AFP | G10: Habitat (flujo) | H10: 0 | I10: 0 | J10: 0 | K10: =C10/DIAS_MES/HORAS_DIA -> 10.416667 | L10: =ROUND(C10/DIAS_MES*D10,2) -> 2500 | M10: =IF(E10="Sí",ASIG_FAMILIAR,0) -> 0 | N10: =ROUND(K10*(1+RECARGO_25)*H10,2) -> 0 | O10: =ROUND(K10*(1+RECARGO_35)*I10,2) -> 0 | P10: =SUM(L10:O10) -> 2500 | Q10: =IF(F10="ONP",ROUND(P10*TASA_ONP,2),0) -> 0 | R10: =IF(F10="AFP",ROUND(P10*IFERROR(VLOOKUP(G10,TABLA_AFP,2,FALSE()),0),2),0) -> 250 | S10: =IF(F10="AFP",ROUND(P10*IFERROR(VLOOKUP(G10,TABLA_AFP,3,FALSE()),0),2),0) -> 36.75 | T10: =IF(F10="AFP",ROUND(P10*IFERROR(VLOOKUP(G10,TABLA_AFP,4,FALSE()),0),2),0) -> 34.25 | U10: =ROUND(J10,2) -> 0 | V10: =SUM(Q10:U10) -> 321 | W10: =P10-V10 -> 2179 | X10: =ROUND(P10*TASA_ESSALUD,2) -> 225 | Y10: =IF(P10=0,0,W10/P10) -> 0.8716 | Z10: — | AA10: 2500 | AB10: 321 | AC10: 2179 | AD10: 225 | AE10: =ROUND(IF(AA10="",0,ABS(P10-AA10))+IF(AB10="",0,ABS(V10-AB10))+IF(AC10="",0,ABS(W10-AC10))+IF(AD10="",0,ABS(X10-AD10)),2) -> 0 | AF10: =IF(AE10<>0,"Revisar",IF(Z10="—","Sí",IF(ROUND(W10-Z10,2)=0,"Sí","Revisar"))) -> Sí
A12: Casos propios: sueldos tomados de ofertas publicadas (enlaces y fechas en la hoja Explicación). Personas y empresas de la boleta son ficticias.
A15: Escenarios usados en las preguntas de análisis
A16: Caso | B16: Descripción | C16: Sueldo | D16: Días | E16: Hijos | F16: Sistema | G16: AFP | H16: HE 25% | I16: HE 35% | J16: Adelanto | K16: Valor hora | L16: Sueldo computable | M16: Asig. familiar | N16: HE 25% S/ | O16: HE 35% S/ | P16: Total remuneraciones | Q16: ONP | R16: AFP fondo | S16: AFP comisión | T16: AFP seguro | U16: Adelantos | V16: Total descuentos | W16: Neto a pagar | X16: EsSalud | Y16: % neto / bruto
A17: P1-ONP | B17: Caso 3 pero con ONP | C17: 3000 | D17: 30 | E17: Sí | F17: ONP | G17: AFP Ejemplo | H17: 4 | I17: 4 | J17: 200 | K17: =C17/DIAS_MES/HORAS_DIA -> 12.5 | L17: =ROUND(C17/DIAS_MES*D17,2) -> 3000 | M17: =IF(E17="Sí",ASIG_FAMILIAR,0) -> 123 | N17: =ROUND(K17*(1+RECARGO_25)*H17,2) -> 62.5 | O17: =ROUND(K17*(1+RECARGO_35)*I17,2) -> 67.5 | P17: =SUM(L17:O17) -> 3253 | Q17: =IF(F17="ONP",ROUND(P17*TASA_ONP,2),0) -> 422.89 | R17: =IF(F17="AFP",ROUND(P17*IFERROR(VLOOKUP(G17,TABLA_AFP,2,FALSE()),0),2),0) -> 0 | S17: =IF(F17="AFP",ROUND(P17*IFERROR(VLOOKUP(G17,TABLA_AFP,3,FALSE()),0),2),0) -> 0 | T17: =IF(F17="AFP",ROUND(P17*IFERROR(VLOOKUP(G17,TABLA_AFP,4,FALSE()),0),2),0) -> 0 | U17: =ROUND(J17,2) -> 200 | V17: =SUM(Q17:U17) -> 622.89 | W17: =P17-V17 -> 2630.11 | X17: =ROUND(P17*TASA_ESSALUD,2) -> 292.77 | Y17: =IF(P17=0,0,W17/P17) -> 0.80851829
A18: P3-30d | B18: Caso 2 pero con 30 días | C18: 1800 | D18: 30 | E18: Sí | F18: ONP | G18: AFP Ejemplo | H18: 0 | I18: 0 | J18: 0 | K18: =C18/DIAS_MES/HORAS_DIA -> 7.5 | L18: =ROUND(C18/DIAS_MES*D18,2) -> 1800 | M18: =IF(E18="Sí",ASIG_FAMILIAR,0) -> 123 | N18: =ROUND(K18*(1+RECARGO_25)*H18,2) -> 0 | O18: =ROUND(K18*(1+RECARGO_35)*I18,2) -> 0 | P18: =SUM(L18:O18) -> 1923 | Q18: =IF(F18="ONP",ROUND(P18*TASA_ONP,2),0) -> 249.99 | R18: =IF(F18="AFP",ROUND(P18*IFERROR(VLOOKUP(G18,TABLA_AFP,2,FALSE()),0),2),0) -> 0 | S18: =IF(F18="AFP",ROUND(P18*IFERROR(VLOOKUP(G18,TABLA_AFP,3,FALSE()),0),2),0) -> 0 | T18: =IF(F18="AFP",ROUND(P18*IFERROR(VLOOKUP(G18,TABLA_AFP,4,FALSE()),0),2),0) -> 0 | U18: =ROUND(J18,2) -> 0 | V18: =SUM(Q18:U18) -> 249.99 | W18: =P18-V18 -> 1673.01 | X18: =ROUND(P18*TASA_ESSALUD,2) -> 173.07 | Y18: =IF(P18=0,0,W18/P18) -> 0.87
A21: Registro libre: copia aquí lo que ingreses en la app y lo que te muestra
A22: Llena las celdas amarillas con los mismos datos del formulario de la app y, a la derecha, los totales que salen en la boleta de la app. La columna ¿Coincide? dice si el Excel da lo mismo al centavo.
A23: Caso | B23: Descripción | C23: Sueldo | D23: Días | E23: Hijos | F23: Sistema | G23: AFP | H23: HE 25% | I23: HE 35% | J23: Adelanto | K23: Valor hora | L23: Sueldo computable | M23: Asig. familiar | N23: HE 25% S/ | O23: HE 35% S/ | P23: Total remuneraciones | Q23: ONP | R23: AFP fondo | S23: AFP comisión | T23: AFP seguro | U23: Adelantos | V23: Total descuentos | W23: Neto a pagar | X23: EsSalud | Y23: % neto / bruto | Z23: Neto esperado (enunciado) | AA23: Total rem. app | AB23: Total desc. app | AC23: Neto app | AD23: EsSalud app | AE23: Diferencia Excel − app | AF23: ¿Coincide?
A24: Libre 1 | K24: =IF($C24="","",C24/DIAS_MES/HORAS_DIA) | L24: =IF($C24="","",ROUND(C24/DIAS_MES*D24,2)) | M24: =IF($C24="","",IF(E24="Sí",ASIG_FAMILIAR,0)) | N24: =IF($C24="","",ROUND(K24*(1+RECARGO_25)*H24,2)) | O24: =IF($C24="","",ROUND(K24*(1+RECARGO_35)*I24,2)) | P24: =IF($C24="","",SUM(L24:O24)) | Q24: =IF($C24="","",IF(F24="ONP",ROUND(P24*TASA_ONP,2),0)) | R24: =IF($C24="","",IF(F24="AFP",ROUND(P24*IFERROR(VLOOKUP(G24,TABLA_AFP,2,FALSE()),0),2),0)) | S24: =IF($C24="","",IF(F24="AFP",ROUND(P24*IFERROR(VLOOKUP(G24,TABLA_AFP,3,FALSE()),0),2),0)) | T24: =IF($C24="","",IF(F24="AFP",ROUND(P24*IFERROR(VLOOKUP(G24,TABLA_AFP,4,FALSE()),0),2),0)) | U24: =IF($C24="","",ROUND(J24,2)) | V24: =IF($C24="","",SUM(Q24:U24)) | W24: =IF($C24="","",P24-V24) | X24: =IF($C24="","",ROUND(P24*TASA_ESSALUD,2)) | Y24: =IF($C24="","",IF(P24=0,0,W24/P24)) | Z24: — | AE24: =IF(OR($C24="",$AC24=""),"",ROUND(IF(AA24="",0,ABS(P24-AA24))+IF(AB24="",0,ABS(V24-AB24))+IF(AC24="",0,ABS(W24-AC24))+IF(AD24="",0,ABS(X24-AD24)),2)) | AF24: =IF(OR($C24="",$AC24=""),"",IF(AE24<>0,"Revisar",IF(Z24="—","Sí",IF(ROUND(W24-Z24,2)=0,"Sí","Revisar"))))
A25: Libre 2 | K25: =IF($C25="","",C25/DIAS_MES/HORAS_DIA) | L25: =IF($C25="","",ROUND(C25/DIAS_MES*D25,2)) | M25: =IF($C25="","",IF(E25="Sí",ASIG_FAMILIAR,0)) | N25: =IF($C25="","",ROUND(K25*(1+RECARGO_25)*H25,2)) | O25: =IF($C25="","",ROUND(K25*(1+RECARGO_35)*I25,2)) | P25: =IF($C25="","",SUM(L25:O25)) | Q25: =IF($C25="","",IF(F25="ONP",ROUND(P25*TASA_ONP,2),0)) | R25: =IF($C25="","",IF(F25="AFP",ROUND(P25*IFERROR(VLOOKUP(G25,TABLA_AFP,2,FALSE()),0),2),0)) | S25: =IF($C25="","",IF(F25="AFP",ROUND(P25*IFERROR(VLOOKUP(G25,TABLA_AFP,3,FALSE()),0),2),0)) | T25: =IF($C25="","",IF(F25="AFP",ROUND(P25*IFERROR(VLOOKUP(G25,TABLA_AFP,4,FALSE()),0),2),0)) | U25: =IF($C25="","",ROUND(J25,2)) | V25: =IF($C25="","",SUM(Q25:U25)) | W25: =IF($C25="","",P25-V25) | X25: =IF($C25="","",ROUND(P25*TASA_ESSALUD,2)) | Y25: =IF($C25="","",IF(P25=0,0,W25/P25)) | Z25: — | AE25: =IF(OR($C25="",$AC25=""),"",ROUND(IF(AA25="",0,ABS(P25-AA25))+IF(AB25="",0,ABS(V25-AB25))+IF(AC25="",0,ABS(W25-AC25))+IF(AD25="",0,ABS(X25-AD25)),2)) | AF25: =IF(OR($C25="",$AC25=""),"",IF(AE25<>0,"Revisar",IF(Z25="—","Sí",IF(ROUND(W25-Z25,2)=0,"Sí","Revisar"))))
A26: Libre 3 | K26: =IF($C26="","",C26/DIAS_MES/HORAS_DIA) | L26: =IF($C26="","",ROUND(C26/DIAS_MES*D26,2)) | M26: =IF($C26="","",IF(E26="Sí",ASIG_FAMILIAR,0)) | N26: =IF($C26="","",ROUND(K26*(1+RECARGO_25)*H26,2)) | O26: =IF($C26="","",ROUND(K26*(1+RECARGO_35)*I26,2)) | P26: =IF($C26="","",SUM(L26:O26)) | Q26: =IF($C26="","",IF(F26="ONP",ROUND(P26*TASA_ONP,2),0)) | R26: =IF($C26="","",IF(F26="AFP",ROUND(P26*IFERROR(VLOOKUP(G26,TABLA_AFP,2,FALSE()),0),2),0)) | S26: =IF($C26="","",IF(F26="AFP",ROUND(P26*IFERROR(VLOOKUP(G26,TABLA_AFP,3,FALSE()),0),2),0)) | T26: =IF($C26="","",IF(F26="AFP",ROUND(P26*IFERROR(VLOOKUP(G26,TABLA_AFP,4,FALSE()),0),2),0)) | U26: =IF($C26="","",ROUND(J26,2)) | V26: =IF($C26="","",SUM(Q26:U26)) | W26: =IF($C26="","",P26-V26) | X26: =IF($C26="","",ROUND(P26*TASA_ESSALUD,2)) | Y26: =IF($C26="","",IF(P26=0,0,W26/P26)) | Z26: — | AE26: =IF(OR($C26="",$AC26=""),"",ROUND(IF(AA26="",0,ABS(P26-AA26))+IF(AB26="",0,ABS(V26-AB26))+IF(AC26="",0,ABS(W26-AC26))+IF(AD26="",0,ABS(X26-AD26)),2)) | AF26: =IF(OR($C26="",$AC26=""),"",IF(AE26<>0,"Revisar",IF(Z26="—","Sí",IF(ROUND(W26-Z26,2)=0,"Sí","Revisar"))))
A27: Libre 4 | K27: =IF($C27="","",C27/DIAS_MES/HORAS_DIA) | L27: =IF($C27="","",ROUND(C27/DIAS_MES*D27,2)) | M27: =IF($C27="","",IF(E27="Sí",ASIG_FAMILIAR,0)) | N27: =IF($C27="","",ROUND(K27*(1+RECARGO_25)*H27,2)) | O27: =IF($C27="","",ROUND(K27*(1+RECARGO_35)*I27,2)) | P27: =IF($C27="","",SUM(L27:O27)) | Q27: =IF($C27="","",IF(F27="ONP",ROUND(P27*TASA_ONP,2),0)) | R27: =IF($C27="","",IF(F27="AFP",ROUND(P27*IFERROR(VLOOKUP(G27,TABLA_AFP,2,FALSE()),0),2),0)) | S27: =IF($C27="","",IF(F27="AFP",ROUND(P27*IFERROR(VLOOKUP(G27,TABLA_AFP,3,FALSE()),0),2),0)) | T27: =IF($C27="","",IF(F27="AFP",ROUND(P27*IFERROR(VLOOKUP(G27,TABLA_AFP,4,FALSE()),0),2),0)) | U27: =IF($C27="","",ROUND(J27,2)) | V27: =IF($C27="","",SUM(Q27:U27)) | W27: =IF($C27="","",P27-V27) | X27: =IF($C27="","",ROUND(P27*TASA_ESSALUD,2)) | Y27: =IF($C27="","",IF(P27=0,0,W27/P27)) | Z27: — | AE27: =IF(OR($C27="",$AC27=""),"",ROUND(IF(AA27="",0,ABS(P27-AA27))+IF(AB27="",0,ABS(V27-AB27))+IF(AC27="",0,ABS(W27-AC27))+IF(AD27="",0,ABS(X27-AD27)),2)) | AF27: =IF(OR($C27="",$AC27=""),"",IF(AE27<>0,"Revisar",IF(Z27="—","Sí",IF(ROUND(W27-Z27,2)=0,"Sí","Revisar"))))
A28: Libre 5 | K28: =IF($C28="","",C28/DIAS_MES/HORAS_DIA) | L28: =IF($C28="","",ROUND(C28/DIAS_MES*D28,2)) | M28: =IF($C28="","",IF(E28="Sí",ASIG_FAMILIAR,0)) | N28: =IF($C28="","",ROUND(K28*(1+RECARGO_25)*H28,2)) | O28: =IF($C28="","",ROUND(K28*(1+RECARGO_35)*I28,2)) | P28: =IF($C28="","",SUM(L28:O28)) | Q28: =IF($C28="","",IF(F28="ONP",ROUND(P28*TASA_ONP,2),0)) | R28: =IF($C28="","",IF(F28="AFP",ROUND(P28*IFERROR(VLOOKUP(G28,TABLA_AFP,2,FALSE()),0),2),0)) | S28: =IF($C28="","",IF(F28="AFP",ROUND(P28*IFERROR(VLOOKUP(G28,TABLA_AFP,3,FALSE()),0),2),0)) | T28: =IF($C28="","",IF(F28="AFP",ROUND(P28*IFERROR(VLOOKUP(G28,TABLA_AFP,4,FALSE()),0),2),0)) | U28: =IF($C28="","",ROUND(J28,2)) | V28: =IF($C28="","",SUM(Q28:U28)) | W28: =IF($C28="","",P28-V28) | X28: =IF($C28="","",ROUND(P28*TASA_ESSALUD,2)) | Y28: =IF($C28="","",IF(P28=0,0,W28/P28)) | Z28: — | AE28: =IF(OR($C28="",$AC28=""),"",ROUND(IF(AA28="",0,ABS(P28-AA28))+IF(AB28="",0,ABS(V28-AB28))+IF(AC28="",0,ABS(W28-AC28))+IF(AD28="",0,ABS(X28-AD28)),2)) | AF28: =IF(OR($C28="",$AC28=""),"",IF(AE28<>0,"Revisar",IF(Z28="—","Sí",IF(ROUND(W28-Z28,2)=0,"Sí","Revisar"))))
A29: Libre 6 | K29: =IF($C29="","",C29/DIAS_MES/HORAS_DIA) | L29: =IF($C29="","",ROUND(C29/DIAS_MES*D29,2)) | M29: =IF($C29="","",IF(E29="Sí",ASIG_FAMILIAR,0)) | N29: =IF($C29="","",ROUND(K29*(1+RECARGO_25)*H29,2)) | O29: =IF($C29="","",ROUND(K29*(1+RECARGO_35)*I29,2)) | P29: =IF($C29="","",SUM(L29:O29)) | Q29: =IF($C29="","",IF(F29="ONP",ROUND(P29*TASA_ONP,2),0)) | R29: =IF($C29="","",IF(F29="AFP",ROUND(P29*IFERROR(VLOOKUP(G29,TABLA_AFP,2,FALSE()),0),2),0)) | S29: =IF($C29="","",IF(F29="AFP",ROUND(P29*IFERROR(VLOOKUP(G29,TABLA_AFP,3,FALSE()),0),2),0)) | T29: =IF($C29="","",IF(F29="AFP",ROUND(P29*IFERROR(VLOOKUP(G29,TABLA_AFP,4,FALSE()),0),2),0)) | U29: =IF($C29="","",ROUND(J29,2)) | V29: =IF($C29="","",SUM(Q29:U29)) | W29: =IF($C29="","",P29-V29) | X29: =IF($C29="","",ROUND(P29*TASA_ESSALUD,2)) | Y29: =IF($C29="","",IF(P29=0,0,W29/P29)) | Z29: — | AE29: =IF(OR($C29="",$AC29=""),"",ROUND(IF(AA29="",0,ABS(P29-AA29))+IF(AB29="",0,ABS(V29-AB29))+IF(AC29="",0,ABS(W29-AC29))+IF(AD29="",0,ABS(X29-AD29)),2)) | AF29: =IF(OR($C29="",$AC29=""),"",IF(AE29<>0,"Revisar",IF(Z29="—","Sí",IF(ROUND(W29-Z29,2)=0,"Sí","Revisar"))))
A30: Libre 7 | K30: =IF($C30="","",C30/DIAS_MES/HORAS_DIA) | L30: =IF($C30="","",ROUND(C30/DIAS_MES*D30,2)) | M30: =IF($C30="","",IF(E30="Sí",ASIG_FAMILIAR,0)) | N30: =IF($C30="","",ROUND(K30*(1+RECARGO_25)*H30,2)) | O30: =IF($C30="","",ROUND(K30*(1+RECARGO_35)*I30,2)) | P30: =IF($C30="","",SUM(L30:O30)) | Q30: =IF($C30="","",IF(F30="ONP",ROUND(P30*TASA_ONP,2),0)) | R30: =IF($C30="","",IF(F30="AFP",ROUND(P30*IFERROR(VLOOKUP(G30,TABLA_AFP,2,FALSE()),0),2),0)) | S30: =IF($C30="","",IF(F30="AFP",ROUND(P30*IFERROR(VLOOKUP(G30,TABLA_AFP,3,FALSE()),0),2),0)) | T30: =IF($C30="","",IF(F30="AFP",ROUND(P30*IFERROR(VLOOKUP(G30,TABLA_AFP,4,FALSE()),0),2),0)) | U30: =IF($C30="","",ROUND(J30,2)) | V30: =IF($C30="","",SUM(Q30:U30)) | W30: =IF($C30="","",P30-V30) | X30: =IF($C30="","",ROUND(P30*TASA_ESSALUD,2)) | Y30: =IF($C30="","",IF(P30=0,0,W30/P30)) | Z30: — | AE30: =IF(OR($C30="",$AC30=""),"",ROUND(IF(AA30="",0,ABS(P30-AA30))+IF(AB30="",0,ABS(V30-AB30))+IF(AC30="",0,ABS(W30-AC30))+IF(AD30="",0,ABS(X30-AD30)),2)) | AF30: =IF(OR($C30="",$AC30=""),"",IF(AE30<>0,"Revisar",IF(Z30="—","Sí",IF(ROUND(W30-Z30,2)=0,"Sí","Revisar"))))
A31: Libre 8 | K31: =IF($C31="","",C31/DIAS_MES/HORAS_DIA) | L31: =IF($C31="","",ROUND(C31/DIAS_MES*D31,2)) | M31: =IF($C31="","",IF(E31="Sí",ASIG_FAMILIAR,0)) | N31: =IF($C31="","",ROUND(K31*(1+RECARGO_25)*H31,2)) | O31: =IF($C31="","",ROUND(K31*(1+RECARGO_35)*I31,2)) | P31: =IF($C31="","",SUM(L31:O31)) | Q31: =IF($C31="","",IF(F31="ONP",ROUND(P31*TASA_ONP,2),0)) | R31: =IF($C31="","",IF(F31="AFP",ROUND(P31*IFERROR(VLOOKUP(G31,TABLA_AFP,2,FALSE()),0),2),0)) | S31: =IF($C31="","",IF(F31="AFP",ROUND(P31*IFERROR(VLOOKUP(G31,TABLA_AFP,3,FALSE()),0),2),0)) | T31: =IF($C31="","",IF(F31="AFP",ROUND(P31*IFERROR(VLOOKUP(G31,TABLA_AFP,4,FALSE()),0),2),0)) | U31: =IF($C31="","",ROUND(J31,2)) | V31: =IF($C31="","",SUM(Q31:U31)) | W31: =IF($C31="","",P31-V31) | X31: =IF($C31="","",ROUND(P31*TASA_ESSALUD,2)) | Y31: =IF($C31="","",IF(P31=0,0,W31/P31)) | Z31: — | AE31: =IF(OR($C31="",$AC31=""),"",ROUND(IF(AA31="",0,ABS(P31-AA31))+IF(AB31="",0,ABS(V31-AB31))+IF(AC31="",0,ABS(W31-AC31))+IF(AD31="",0,ABS(X31-AD31)),2)) | AF31: =IF(OR($C31="",$AC31=""),"",IF(AE31<>0,"Revisar",IF(Z31="—","Sí",IF(ROUND(W31-Z31,2)=0,"Sí","Revisar"))))

Sheet Explicación
A1: Explicación de cada fórmula (para alguien que no sabe contabilidad)
A2: Los ejemplos numéricos son del caso 3: sueldo S/ 3,000, 30 días, con hijos, AFP Ejemplo, 4 h al 25%, 4 h al 35%, adelanto S/ 200. Los números de la columna D se calculan solos desde la hoja Casos.
A3: En Excel en español las funciones se ven traducidas: ROUND = REDONDEAR, IF = SI, VLOOKUP = BUSCARV, IFERROR = SI.ERROR, SUM = SUMA.
A4: Concepto | B4: Fórmula en Excel (hoja Boleta) | C4: Explicado en palabras | D4: Ejemplo (caso 3) | E4: Resultado
A5: Sueldo computable | B5: =ROUND(B5/DIAS_MES*B6,2) | C5: El sueldo pactado es por 30 días. Se divide entre 30 para saber cuánto vale un día y se multiplica por los días que de verdad trabajó. Si faltó, ya está restado aquí. | D5: 3,000 ÷ 30 × 30 | E5: =Casos!L7 -> 3000
A6: Asignación familiar | B6: =IF(B7="Sí",ASIG_FAMILIAR,0) | C6: Si el trabajador tiene hijos recibe el 10% del sueldo mínimo (RMV). Es un monto fijo: no importa cuántos días trabajó ni cuántos hijos tenga. | D6: 10% × 1,230 | E6: =Casos!M7 -> 123
A7: Valor hora | B7: =B5/DIAS_MES/HORAS_DIA | C7: Cuánto gana por una hora normal: el sueldo entre 30 días y entre 8 horas. No se redondea porque solo sirve para calcular las horas extras. | D7: 3,000 ÷ 30 ÷ 8 | E7: =Casos!K7 -> 12.5
A8: Horas extras 25% | B8: =ROUND(B15*(1+RECARGO_25)*B10,2) | C8: Las primeras horas extra se pagan 25% más caras que una hora normal: valor hora × 1.25 × número de horas. | D8: 12.50 × 1.25 × 4 | E8: =Casos!N7 -> 62.5
A9: Horas extras 35% | B9: =ROUND(B15*(1+RECARGO_35)*B11,2) | C9: Las siguientes horas extra se pagan 35% más caras: valor hora × 1.35 × número de horas. | D9: 12.50 × 1.35 × 4 | E9: =Casos!O7 -> 67.5
A10: Total remuneraciones | B10: =SUM(B18:B21) | C10: Todo lo que gana en el mes antes de descuentos (el 'bruto'). Es la base para calcular pensión y EsSalud. | D10: 3,000 + 123 + 62.50 + 67.50 | E10: =Casos!P7 -> 3253
A11: ONP | B11: =IF(B8="ONP",ROUND(B23*TASA_ONP,2),0) | C11: Si está en la ONP (sistema público), se le descuenta el 13% del total de remuneraciones. Si está en AFP, este descuento es 0. | D11: No aplica (está en AFP) | E11: =Casos!Q7 -> 0
A12: AFP fondo | B12: =IF(B8="AFP",ROUND(B23*IFERROR(VLOOKUP(B9,TABLA_AFP,2,FALSE),0),2),0) | C12: Si está en una AFP, el 10% va a su cuenta personal de jubilación. BUSCARV busca la AFP elegida en la tabla de Parámetros y trae su tasa (SI.ERROR pone 0 si la AFP no está en la lista). | D12: 3,253 × 10% | E12: =Casos!R7 -> 325.3
A13: AFP comisión | B13: =IF(B8="AFP",ROUND(B23*IFERROR(VLOOKUP(B9,TABLA_AFP,3,FALSE),0),2),0) | C13: Lo que cobra la AFP por administrar el dinero. Cada AFP tiene su propia tasa. | D13: 3,253 × 1.60% = 52.048 | E13: =Casos!S7 -> 52.05
A14: AFP seguro | B14: =IF(B8="AFP",ROUND(B23*IFERROR(VLOOKUP(B9,TABLA_AFP,4,FALSE),0),2),0) | C14: Seguro de invalidez y sobrevivencia que se paga dentro de la AFP. | D14: 3,253 × 1.35% = 43.9155 | E14: =Casos!T7 -> 43.92
A15: Adelantos | B15: =ROUND(B12,2) | C15: Plata que el trabajador ya recibió antes durante el mes. Se resta tal cual. | D15: Monto ingresado | E15: =Casos!U7 -> 200
A16: Total descuentos | B16: =SUM(D18:D22) | C16: Pensión (ONP o AFP) más adelantos. | D16: 325.30 + 52.05 + 43.92 + 200 | E16: =Casos!V7 -> 621.27
A17: Neto a pagar | B17: =IF(B14="OK",B23-D23,"—") | C17: Lo que de verdad llega al bolsillo: lo que gana menos lo que le descuentan. Si algún dato está mal no se calcula (igual que la app) y la validación dice qué corregir. | D17: 3,253 − 621.27 | E17: =Casos!W7 -> 2631.73
A18: EsSalud | B18: =ROUND(B23*TASA_ESSALUD,2) | C18: Seguro de salud del trabajador. Lo paga la empresa (9% del total de remuneraciones), por eso NO se resta del neto. | D18: 3,253 × 9% | E18: =Casos!X7 -> 292.77
A19: Redondeo | B19: ROUND(valor,2) | C19: Cada concepto se redondea a 2 decimales (céntimos) ANTES de sumar. Por ejemplo 52.048 queda 52.05. Así la app y el Excel dan lo mismo al centavo. | D19: 52.048 → 52.05 | E19: =Casos!S7 -> 52.05
A22: Preguntas de análisis
A23: Pregunta | B23: Dato clave | C23: Respuesta | D23: Valor | E23: Unidad
A24: 1. ONP o AFP (caso 3) | B24: Neto con AFP Ejemplo vs. neto con ONP | C24: Este mes deja más plata la AFP, pero por muy poco (S/ 1.62). No basta comparar porcentajes porque no son lo mismo: el 13% de la ONP va a un fondo común y para cobrar pensión hay que aportar al menos 20 años; en la AFP el 10% es ahorro propio (sigue siendo del trabajador y crece con la rentabilidad), pero la comisión y el seguro sí son costo. Además la comisión cambia según la AFP y la pensión final depende de la rentabilidad y de cuántos años aporte. | D24: =Casos!W7-Casos!W17 -> 1.62 | E24: S/ más con AFP
A25: 2. Costo real para la empresa (caso 3) | B25: Remuneraciones + EsSalud | C25: Al empleador el trabajador le cuesta remuneraciones más EsSalud. De ese costo, al trabajador le llega como neto el porcentaje de la fila de abajo; el resto se va en pensión, adelanto (que ya cobró antes) y EsSalud. | D25: =Casos!P7+Casos!X7 -> 3545.77 | E25: S/ costo total
B26: % del costo que llega como neto | D26: =Casos!W7/(Casos!P7+Casos!X7) -> 0.74221678 | E26: %
A27: 3. Días laborados (caso 2) | B27: Neto con 30 días − neto con 27 días | C27: Con 30 días el bruto sube S/ 180 (3 días × S/ 60), pero el neto sube menos porque de esos S/ 180 se descuenta 13% de ONP (S/ 23.40). La asignación familiar no cambia porque no se prorratea. | D27: =Casos!W18-Casos!W6 -> 156.6 | E27: S/ de diferencia en neto
B28: Diferencia en el bruto | D28: =Casos!P18-Casos!P6 -> 180 | E28: S/ de diferencia en bruto
A29: 4. Horas extras (caso 3) | B29: (HE 25% + HE 35%) ÷ total remuneraciones | C29: Las 8 horas extras (S/ 130) son casi el 4% de todo lo que ganó en el mes. | D29: =(Casos!N7+Casos!O7)/Casos!P7 -> 0.039963111 | E29: %
A30: 5. Con datos reales | B30: % del sueldo bruto que llega al trabajador | C30: Con mi caso propio (S/ 2,300, ONP) llega el 87.00% del bruto y con el segundo sueldo real (S/ 2,500, AFP Habitat) el 87.16%. Casi igual, porque los descuentos son porcentajes fijos del bruto: ganar más no cambia la proporción. Lo que la mueve es el sistema (ONP 13%; AFP reales entre 12.84% y 13.06% según la comisión), la asignación familiar y los adelantos. Para comparar con dos compañeros, sus sueldos se registran en 'Registro libre' de la hoja Casos (filas Libre 1 y Libre 2) y su % sale abajo. | D30: =Casos!Y9 -> 0.87 | E30: % Propio 1 (ONP)
D31: =Casos!Y10 -> 0.8716 | E31: % Propio 2 (AFP Habitat)
D32: =Casos!Y24 | E32: % Compañero 1 (Libre 1)
D33: =Casos!Y25 | E33: % Compañero 2 (Libre 2)
A36: Tabla de fuentes
A37: Dato | B37: Valor | C37: Fuente | D37: Enlace | E37: Fecha de consulta
A38: RMV | B38: S/ 1,230.00 | C38: D.S. N.° 015-2026-TR, El Peruano (28/09/2026) | D38: https://busquedas.elperuano.pe/dispositivo/EX/2559163-1 | E38: 28/10/2026
A39: Asignación familiar | B39: 10% de la RMV = S/ 123.00 | C39: Ley 25129 | D39: — | E39: 28/10/2026
A40: ONP | B40: 13% | C40: D.L. 19990 | D40: — | E40: 28/10/2026
A41: EsSalud | B41: 9% | C41: Ley 26790 | D41: — | E41: 28/10/2026
A42: Horas extras | B42: 25% / 35% | C42: D.S. 007-2002-TR | D42: — | E42: 28/10/2026
A43: Comisiones AFP (flujo) | B43: Habitat 1.47% · Integra 1.55% · Prima 1.60% · Profuturo 1.69% | C43: SBS, devengue oct-2026 | D43: https://www.sbs.gob.pe/app/spp/empleadores/comisiones_spp/paginas/comision_prima.aspx | E43: 28/10/2026
A44: Prima de seguro AFP | B44: 1.37% (tope S/ 12,732.70) | C44: SBS, devengue oct-2026 | D44: https://www.sbs.gob.pe/app/spp/empleadores/comisiones_spp/paginas/comision_prima.aspx | E44: 28/10/2026
...
